When a task catches :exc:`asyncio.CancelledError` and raises some other error,
the other error should generally not silently be suppressed.
