Fixed a crash when calling ``.with_traceback(None)`` on ``NameError``. This occurs internally in ``unittest.TestCase.assertRaises()``.